package coroutines

import kotlinx.coroutines.*
import java.io.IOException

fun main() = runBlocking {
    runUnwrappedExceptions()
}

@OptIn(DelicateCoroutinesApi::class)
suspend fun runExceptionsFromCoroutines() {
    val job = GlobalScope.launch { // root coroutine with launch
        println("Throwing exception from launch")
        throw IndexOutOfBoundsException() // Will be printed to the console by Thread.defaultUncaughtExceptionHandler
    }
    job.join()
    println("Joined failed job")
    val deferred = GlobalScope.async { // root coroutine with async
        println("Throwing exception from async")
        throw ArithmeticException() // Nothing is printed, relying on user to call await
    }
    try {
        deferred.await()
        println("Unreached")
    } catch (e: ArithmeticException) {
        println("Caught ArithmeticException")
    }
}

@OptIn(DelicateCoroutinesApi::class)
suspend fun runExceptionFromDeferred() {
    val handler = CoroutineExceptionHandler { _, exception ->
        println("CoroutineExceptionHandler got $exception")
    }
    val job = GlobalScope.launch(handler) { // root coroutine, running in GlobalScope
        throw AssertionError()
    }
    val deferred = GlobalScope.async(handler) { // also root, but async instead of launch
        throw ArithmeticException() // Nothing will be printed, relying on user to call deferred.await()
    }
    joinAll(job, deferred)
}

@OptIn(DelicateCoroutinesApi::class)
suspend fun runCancellationChildCoroutines() {
    val handler = CoroutineExceptionHandler { _, exception ->
        println("CoroutineExceptionHandler got $exception")
    }
    val job = GlobalScope.launch(handler) {
        launch { // the first child
            try {
                delay(Long.MAX_VALUE)
            } finally {
                withContext(NonCancellable) {
                    println("Children are cancelled, but exception is not handled until all children terminate")
                    delay(100)
                    println("The first child finished its non cancellable block")
                }
            }
        }
        launch { // the second child
            delay(10)
            println("Second child throws an exception")
            throw ArithmeticException()
        }
    }
    job.join()
}

@OptIn(DelicateCoroutinesApi::class)
suspend fun runUnwrappedExceptions() {
    val handler = CoroutineExceptionHandler { _, exception ->
        println("CoroutineExceptionHandler got $exception")
    }
    val job = GlobalScope.launch(handler) {
        val innerJob = launch { // all this stack of coroutines will get cancelled
            launch {
                launch {
                    throw IOException() // the original exception
                }
            }
        }
        try {
            innerJob.join()
        } catch (e: CancellationException) {
            println("message: ${e.message}, cause: ${e.cause}")
            println("Rethrowing CancellationException with original cause")
            throw e // cancellation exception is rethrown, yet the original IOException gets to the handler
        }
        println("Global job is ended")
    }
    job.join()
}